Question:

**Where is a the exception caught if a coroutine started with async throws an exception?**

<div class="hint">
  The parent however the exception will be thrown in the await call.
</div>

